<?xml version="1.0" encoding="utf-8"?>
<!-- This URDF was automatically created by SolidWorks to URDF Exporter! Originally created by Stephen Brawner (brawner@gmail.com) 
     Commit Version: 1.6.0-4-g7f85cfe  Build Version: 1.6.7995.38578
     For more information, please see http://wiki.ros.org/sw_urdf_exporter -->
<robot
  name="bp001_description">
  <link
    name="base_link">
    <inertial>
      <origin
        xyz="-3.55522513015955E-06 5.92361784514663E-19 0.0409942367796753"
        rpy="0 0 0" />
      <mass
        value="2.25389477631104" />
      <inertia
        ixx="0.0118661025979557"
        ixy="-3.33967645556664E-19"
        ixz="2.40439281764157E-07"
        iyy="0.00466922459360897"
        iyz="-9.06548460364706E-20"
        izz="0.0133992461285469" />
    </inertial>
    <visual>
      <origin
        xyz="0 0 0"
        rpy="0 0 0" />
      <geometry>
        <mesh
          filename="package://bp001_description/meshes/visual/base_link.STL" />
      </geometry>
      <material
        name="">
        <color
          rgba="1 1 1 1" />
      </material>
    </visual>
    <collision>
      <origin
        xyz="0 0 0"
        rpy="0 0 0" />
      <geometry>
        <mesh
          filename="package://bp001_description/meshes/collision/base_link.STL" />
      </geometry>
    </collision>
  </link>
  <link
    name="link_lw">
    <inertial>
      <origin
        xyz="1.52443637758642E-16 0.0173372551398928 -8.03645032440958E-17"
        rpy="0 0 0" />
      <mass
        value="0.234199193964837" />
      <inertia
        ixx="0.000548765971685728"
        ixy="1.99022370076796E-18"
        ixz="-3.48339456124935E-19"
        iyy="0.00104446027104137"
        iyz="9.34394840711479E-19"
        izz="0.000548765971685726" />
    </inertial>
    <visual>
      <origin
        xyz="0 0 0"
        rpy="0 0 0" />
      <geometry>
        <mesh
          filename="package://bp001_description/meshes/visual/link_lw.STL" />
      </geometry>
      <material
        name="">
        <color
          rgba="1 1 1 1" />
      </material>
    </visual>
    <collision>
      <origin
        xyz="0 0 0"
        rpy="0 0 0" />
      <geometry>
        <mesh
          filename="package://bp001_description/meshes/collision/link_lw.STL" />
      </geometry>
    </collision>
  </link>
  <joint
    name="joint_lw"
    type="continuous">
    <origin
      xyz="0 0.1146 0.052"
      rpy="0 0 0" />
    <parent
      link="base_link" />
    <child
      link="link_lw" />
    <axis
      xyz="0 1 0" />
    <limit
      effort="20"
      velocity="30" />
    <dynamics
      damping="0.2"
      friction="0.05" />
  </joint>
  <link
    name="link_rw">
    <inertial>
      <origin
        xyz="-5.82928507239808E-16 -0.0173372551398927 5.41772443989941E-16"
        rpy="0 0 0" />
      <mass
        value="0.234199193964837" />
      <inertia
        ixx="0.000548765971685728"
        ixy="-1.78895729887334E-18"
        ixz="1.32886565406602E-19"
        iyy="0.00104446027104137"
        iyz="1.01812824359612E-18"
        izz="0.000548765971685725" />
    </inertial>
    <visual>
      <origin
        xyz="0 0 0"
        rpy="0 0 0" />
      <geometry>
        <mesh
          filename="package://bp001_description/meshes/visual/link_rw.STL" />
      </geometry>
      <material
        name="">
        <color
          rgba="1 1 1 1" />
      </material>
    </visual>
    <collision>
      <origin
        xyz="0 0 0"
        rpy="0 0 0" />
      <geometry>
        <mesh
          filename="package://bp001_description/meshes/collision/link_rw.STL" />
      </geometry>
    </collision>
  </link>
  <joint
    name="joint_rw"
    type="continuous">
    <origin
      xyz="0 -0.1146 0.052"
      rpy="0 0 0" />
    <parent
      link="base_link" />
    <child
      link="link_rw" />
    <axis
      xyz="0 1 0" />
    <limit
      effort="20"
      velocity="30" />
    <dynamics
      damping="0.2"
      friction="0.05" />
  </joint>
</robot>
